<?xml version="1.0"?>
<robot name="pr2_upper_arm" 
       xmlns:sensor="http://playerstage.sourceforge.net/gazebo/xmlschema/#sensor"
       xmlns:controller="http://playerstage.sourceforge.net/gazebo/xmlschema/#controller"
       xmlns:interface="http://playerstage.sourceforge.net/gazebo/xmlschema/#interface"
       xmlns:xacro="http://ros.org/wiki/xacro">

  <include filename="$(find pr2_description)/urdf/common.xacro" />
  <include filename="$(find pr2_description)/urdf/materials.urdf.xacro" />
  <include filename="$(find pr2_description)/urdf/upper_arm_v0/upper_arm.urdf.xacro" />

  <include filename="$(find pr2_component_descriptions)/urdf/base_link.urdf.xacro" />
  
  <xacro:pr2_upper_arm_v0 side="r" reflect="-1" parent="base_link">
    <origin xyz="0 0 0" rpy="0 0 0" />
  </xacro:pr2_upper_arm_v0>

    <!-- Dummy FA used in burn in test -->
  <joint name="r_dummy_forearm_joint" type="continuous">
    <axis xyz="0 1 0" />
    <limit effort="0" velocity="100"/>
    <safety_controller k_velocity="10" />
    <dynamics damping="0.0" friction="0.0" />
    <origin xyz="0 0 0" rpy="0 0 0" />
    <parent link="r_forearm_roll_link"/>
    <child link="r_dummy_forearm_link"/>
  </joint>
  <link name="r_dummy_forearm_link">
    <inertial>
      <mass value="1" />
      <origin xyz=" 0 0 0 " />
      <inertia  ixx="1.0" ixy="0.0" ixz="0.0"
                iyy="1.0" iyz="0.0" izz="1.0" />
    </inertial>
    <visual>
      <origin xyz="0.10 0 0" rpy="0 0 0" />
      <geometry>
	<box size="0.30 0.10 0.10" />
      </geometry>
    </visual> 
  </link>

  <!-- Transmission uses r_gripper_motor -->
  <transmission type="SimpleTransmission" name="r_dummy_forearm_trans">
    <actuator name="r_wrist_l_motor" />
    <joint name="r_dummy_forearm_joint" />
    <mechanicalReduction>1</mechanicalReduction>
  </transmission>
  
</robot>
