<?xml version="1.0"?>
<robot name="forearm" 
       xmlns:sensor="http://playerstage.sourceforge.net/gazebo/xmlschema/#sensor"
       xmlns:controller="http://playerstage.sourceforge.net/gazebo/xmlschema/#controller"
       xmlns:interface="http://playerstage.sourceforge.net/gazebo/xmlschema/#interface"
       xmlns:xacro="http://ros.org/wiki/xacro">

  <include filename="$(find pr2_description)/urdf/common.xacro" />
  <include filename="$(find pr2_description)/urdf/materials.urdf.xacro" />
  <include filename="$(find pr2_description)/urdf/forearm_v0/forearm.urdf.xacro" />
  <include filename="$(find pr2_description)/urdf/gripper_v0/gripper.urdf.xacro" />

  <include filename="$(find pr2_component_descriptions)/urdf/base_link.urdf.xacro" />

   <!-- generic simulator_gazebo plugins for starting mechanism control, ros time, ros battery -->
  <include filename="$(find pr2_description)/gazebo/gazebo.urdf.xacro" />
  
  
  <xacro:pr2_forearm_v0 side="r" reflect="-1" parent="base_link">
    <origin xyz="0 0 0" rpy="0 0 0" />
  </xacro:pr2_forearm_v0>

  <!-- Dummy gripper used in burn in test -->
  <joint name="r_gripper_fake_joint" type="continuous">
    <axis xyz="0 1 0" />
    <limit effort="100" velocity="100"/>
    <safety_controller k_velocity="10" />
    <dynamics damping="0.0" friction="0.0" />
    <origin xyz="0 0 0" rpy="0 0 0" />
    <parent link="r_wrist_roll_link"/>
    <child link="r_gripper_fake_link"/>
  </joint>
  <link name="r_gripper_fake_link">
    <inertial>
      <mass value="1" />
      <origin xyz=" 0 0 0 " />
      <inertia  ixx="1.0" ixy="0.0" ixz="0.0"
                iyy="1.0" iyz="0.0" izz="1.0" />
    </inertial>

  </link>

  <!-- Transmission uses r_gripper_motor -->
  <transmission type="SimpleTransmission" name="r_gripper_fake_trans">
    <actuator name="r_gripper_motor" />
    <joint name="r_gripper_fake_joint" />
    <mechanicalReduction>1</mechanicalReduction>
  </transmission>

</robot>
