<?xml version="1.0"?>
<robot name="caster_motor">
  <joint name="caster_motor_joint" type="continuous">
    <axis xyz="0 1 0" />
    <limit effort="100" velocity="100"/>
    <safety_controller k_velocity="10" />
    <dynamics damping="0.0" friction="0.0" />
    <origin xyz="0 0 0" rpy="0 0 0" />
    <parent link="world"/>
    <child link="caster_motor_link"/>
  </joint>
  <link name="caster_motor_link">
    <inertial>
      <mass value="1" /> 
      <origin xyz=" 0 0 0 " />
      <inertia  ixx="1.0" ixy="0.0" ixz="0.0"
                iyy="1.0" iyz="0.0" izz="1.0" />
    </inertial>
    
  </link>

  <!-- Transmission uses fl_caster_l_wheel_motor -->
  <transmission type="SimpleTransmission" name="caster_motor_trans">
    <actuator name="fl_caster_l_wheel_motor" />
    <joint name="caster_motor_joint" />
    <mechanicalReduction>${624/35}</mechanicalReduction>
  </transmission>
  
</robot>
